<?xml version="1.0"?>
<robot name="normal_sedan">

  <!-- 基本框架 -->
  <link name="base_link"/>

  <!-- 车身部分 -->
  <link name="car_body">
    <visual>
      <geometry>
        <box size="4.532 1.814 1.496"/> <!-- 车身尺寸 -->
      </geometry>
      <material name="gray"/>
    </visual>
  </link>

  <!-- 轮胎 -->
  <!-- 前左轮 -->
  <link name="front_left_wheel">
    <visual>
      <geometry>
        <cylinder radius="0.7" length="0.2"/> <!-- 轮胎半径调整为0.7m -->
      </geometry>
      <material name="black"/>
    </visual>
  </link>

  <!-- 前右轮 -->
  <link name="front_right_wheel">
    <visual>
      <geometry>
        <cylinder radius="0.7" length="0.2"/>
      </geometry>
      <material name="black"/>
    </visual>
  </link>

  <!-- 后左轮 -->
  <link name="rear_left_wheel">
    <visual>
      <geometry>
        <cylinder radius="0.7" length="0.2"/>
      </geometry>
      <material name="black"/>
    </visual>
  </link>

  <!-- 后右轮 -->
  <link name="rear_right_wheel">
    <visual>
      <geometry>
        <cylinder radius="0.7" length="0.2"/>
      </geometry>
      <material name="black"/>
    </visual>
  </link>

  <!-- 车身与前左轮的连接 -->
  <joint name="front_left_wheel_joint" type="revolute">
    <parent link="car_body"/>
    <child link="front_left_wheel"/>
    <origin xyz="1.024 0.907 0" rpy="0 0 0"/>
    <axis xyz="0 0 1"/>
    <limit effort="50" velocity="1"/>
  </joint>

  <!-- 车身与前右轮的连接 -->
  <joint name="front_right_wheel_joint" type="revolute">
    <parent link="car_body"/>
    <child link="front_right_wheel"/>
    <origin xyz="1.024 -0.907 0" rpy="0 0 0"/>
    <axis xyz="0 0 1"/>
    <limit effort="50" velocity="1"/>
  </joint>

  <!-- 车身与后左轮的连接 -->
  <joint name="rear_left_wheel_joint" type="revolute">
    <parent link="car_body"/>
    <child link="rear_left_wheel"/>
    <origin xyz="-1.626 0.907 0" rpy="0 0 0"/>
    <axis xyz="0 0 1"/>
    <limit effort="50" velocity="1"/>
  </joint>

  <!-- 车身与后右轮的连接 -->
  <joint name="rear_right_wheel_joint" type="revolute">
    <parent link="car_body"/>
    <child link="rear_right_wheel"/>
    <origin xyz="-1.626 -0.907 0" rpy="0 0 0"/>
    <axis xyz="0 0 1"/>
    <limit effort="50" velocity="1"/>
  </joint>

  <!-- 车身与基准框架（base_link）的连接 -->
  <joint name="base_to_car_body" type="fixed">
    <parent link="base_link"/>
    <child link="car_body"/>
    <origin xyz="0 0 0.748" rpy="0 0 0"/> <!-- 车身位于基准参考框架的位置 -->
  </joint>

</robot>
